Workbook
Name ExternalData_3: ' BENGALURU HOUSE PRICE'!$A$1:$D$1256
Name Slicer_Area_Type: #REF!
Name Slicer_location: #REF!
Name Slicer_PRICE: #REF!
Name Slicer_PRICE_CATEGORY: #REF!
Name Slicer_PRICE_CATEGORY1: #REF!
Name Slicer_SIZE__ROOM: #REF!
Name SlicerCache_Table_1_Col_1: #N/A
Name SlicerCache_Table_1_Col_6: #N/A
Name SlicerCache_Table_1_Col_8: #N/A

Sheet Sheet2

Sheet Sheet3
A3: Row Labels | B3: Average of PRICE
A4: Binnamangala | B4: 9000000
A5: Cunningham Road | B5: 12500000
A6: Hunasamaranahalli | B6: 6750000
A7: Sector 1 HSR Layout | B7: 7750000
A8: Siddapura | B8: 8000000
A9: Grand Total | B9: 8800000
A461: Row Labels | B461: Average of PRICE
A462: 1 | B462: 403065.06
A463: 2 | B463: 643970.08
A464: 3 | B464: 1208493.1
A465: 4 | B465: 2281463.4
A466: 5 | B466: 2910697.7
A467: 6 | B467: 2908947.4
A468: 7 | B468: 3248571.4
A469: 8 | B469: 2595000
A470: 9 | B470: 2450000
A471: 10 | B471: 1700000
A472: 11 | B472: 2900000
A473: 14 | B473: 5000000
A474: Grand Total | B474: 1081718.8
A481: Row Labels | B481: Sum of PRICE
A482: Large | B482: 500478800
A483: Medium | B483: 757776150
A484: Small | B484: 99302100
A485: Grand Total | B485: 1357557050
A497: Row Labels | B497: Count of property_type
A498: 600 | B498: 16
A499: 950 | B499: 12
A500: 1000 | B500: 18
A501: 1100 | B501: 17
A502: 1200 | B502: 78
A503: 1500 | B503: 27
A504: 1559 | B504: 31
A505: 1600 | B505: 14
A506: 1800 | B506: 12
A507: 2400 | B507: 13
A508: Grand Total | B508: 238
A1068: Average of PRICE | B1068: Column Labels
A1069: Row Labels | B1069: Binnamangala | C1069: Cunningham Road | D1069: Hunasamaranahalli | E1069: Sector 1 HSR Layout | F1069: Siddapura | G1069: Grand Total
...

Sheet Sheet1
A3: Row Labels | B3: Sum of PRICE
A4: Large | B4: 124580000
A5: Medium | B5: 344673950
A6: Small | B6: 6890000
A7: Grand Total | B7: 476143950
A14: Row Labels | B14: Sum of PRICE
A15: 3 | B15: 476143950
A16: Grand Total | B16: 476143950
A34: Row Labels | B34: Sum of PRICE
A35: 1st Block Jayanagar | B35: 1940000
A36: 2nd Block Hrbr Layout | B36: 900000
A37: 2nd Phase JP Nagar | B37: 4990000
A38: 6th block banashankari 3rd stage, 100 feet ORR | B38: 6600000
A39: 7th Phase JP Nagar | B39: 9910000
A40: 8th block Koramangala | B40: 3000000
A41: 8th Phase JP Nagar | B41: 435000
A42: AECS Layout | B42: 980000
A43: Akshaya Nagar | B43: 5201000
A44: Ambalipura | B44: 2850000
A45: Ambedkar Colony | B45: 1650000
A46: Ambedkar Nagar | B46: 1300000
... A119: Hebbal | B119: 12386800
A120: Hebbal Kempapura | B120: 3300000 | I120: Row Labels | J120: Average of PRICE
A121: Hegde Nagar | B121: 4930000 | J121: 0.31602484
A122: Hennur Road | B122: 8065800 | I122: 1 | J122: 0.33434944
A123: Herohalli | B123: 700000 | I123: 11 | J123: 3.3280369
A124: Hoodi | B124: 2737500 | I124: 2 | J124: 0.54043649
A125: Hoodi Circle, | B125: 790000 | I125: 3 | J125: 0.97168546
A126: Horamavu Agara | B126: 1214800 | I126: 4 | J126: 2.4649079
A127: Horamavu Banaswadi | B127: 1210000 | I127: 5 | J127: 1.9283827
A128: Hosa Road | B128: 1650000 | I128: 6 | J128: 1.9427244
A129: Hosahalli | B129: 700000 | I129: 7 | J129: 4.9920554
A130: Hosakerehalli | B130: 8440000 | I130: 8 | J130: 1.5595551
A131: Hosur Road | B131: 2130000 | I131: 9 | J131: 2.3111368
A132: Hoysalanagar | B132: 570000 | I132: Grand Total | J132: 1
A133: HSR Layout | B133: 1960000
A134: Hulimavu | B134: 1780000
A135: Huskur | B135: 352300
A136: Iblur Village | B136: 2350000
A137: ITI Layout | B137: 750000
...

Sheet Sheet4
A3: 🏠 Bengaluru Housing Price Analysis
X28: -Table1_2!E12:G16

Sheet  BENGALURU HOUSE PRICE
A1: location | B1: property_type | C1: Bedroom | D1: balcony | E1: SIZE _ROOM | F1: Area Type | G1: PRICE | H1: PRICE CATEGORY
A2: Electronic City Phase II | B2: 1056 | C2: 2 | D2: 1 | E2: 2 | F2: =IF(B2>2000,"Large",IF(B2>1000,"Medium","Small")) -> Medium | G2: 390700 | H2: =IF(' BENGALURU HOUSE PRICE'!$G2<=500000,"Low", IF(' BENGALURU HOUSE PRICE'!$G2<=1000000,"Medium", IF(' BENGALURU HOUSE PRICE'!$G2<=3000000,"High","Luxury"))) -> Low
A3: Chikka Tirupathi | B3: 2600 | C3: 5 | D3: 3 | E3: 4 | F3: =IF(B3>2000,"Large",IF(B3>1000,"Medium","Small")) -> Large | G3: 1200000 | H3: =IF(' BENGALURU HOUSE PRICE'!$G3<=500000,"Low", IF(' BENGALURU HOUSE PRICE'!$G3<=1000000,"Medium", IF(' BENGALURU HOUSE PRICE'!$G3<=3000000,"High","Luxury"))) -> High
A4: Uttarahalli | B4: 1440 | C4: 2 | D4: 3 | E4: 3 | F4: =IF(B4>2000,"Large",IF(B4>1000,"Medium","Small")) -> Medium | G4: 620000 | H4: =IF(' BENGALURU HOUSE PRICE'!$G4<=500000,"Low", IF(' BENGALURU HOUSE PRICE'!$G4<=1000000,"Medium", IF(' BENGALURU HOUSE PRICE'!$G4<=3000000,"High","Luxury"))) -> Medium
A5: Lingadheeranahalli | B5: 1521 | C5: 3 | D5: 1 | E5: 3 | F5: =IF(B5>2000,"Large",IF(B5>1000,"Medium","Small")) -> Medium | G5: 950000 | H5: =IF(' BENGALURU HOUSE PRICE'!$G5<=500000,"Low", IF(' BENGALURU HOUSE PRICE'!$G5<=1000000,"Medium", IF(' BENGALURU HOUSE PRICE'!$G5<=3000000,"High","Luxury"))) -> Medium
A6: Kothanur | B6: 1200 | C6: 2 | D6: 1 | E6: 2 | F6: =IF(B6>2000,"Large",IF(B6>1000,"Medium","Small")) -> Medium | G6: 510000 | H6: =IF(' BENGALURU HOUSE PRICE'!$G6<=500000,"Low", IF(' BENGALURU HOUSE PRICE'!$G6<=1000000,"Medium", IF(' BENGALURU HOUSE PRICE'!$G6<=3000000,"High","Luxury"))) -> Medium
A7: Whitefield | B7: 1170 | C7: 2 | D7: 1 | E7: 2 | F7: =IF(B7>2000,"Large",IF(B7>1000,"Medium","Small")) -> Medium | G7: 380000 | H7: =IF(' BENGALURU HOUSE PRICE'!$G7<=500000,"Low", IF(' BENGALURU HOUSE PRICE'!$G7<=1000000,"Medium", IF(' BENGALURU HOUSE PRICE'!$G7<=3000000,"High","Luxury"))) -> Low
A8: Old Airport Road | B8: 2732 | C8: 4 | D8: 2 | E8: 4 | F8: =IF(B8>2000,"Large",IF(B8>1000,"Medium","Small")) -> Large | G8: 2040000 | H8: =IF(' BENGALURU HOUSE PRICE'!$G8<=500000,"Low", IF(' BENGALURU HOUSE PRICE'!$G8<=1000000,"Medium", IF(' BENGALURU HOUSE PRICE'!$G8<=3000000,"High","Luxury"))) -> High
A9: Rajaji Nagar | B9: 3300 | C9: 4 | D9: 2 | E9: 4 | F9: =IF(B9>2000,"Large",IF(B9>1000,"Medium","Small")) -> Large | G9: 6000000 | H9: =IF(' BENGALURU HOUSE PRICE'!$G9<=500000,"Low", IF(' BENGALURU HOUSE PRICE'!$G9<=1000000,"Medium", IF(' BENGALURU HOUSE PRICE'!$G9<=3000000,"High","Luxury"))) -> Luxury
A10: Marathahalli | B10: 1310 | C10: 3 | D10: 1 | E10: 3 | F10: =IF(B10>2000,"Large",IF(B10>1000,"Medium","Small")) -> Medium | G10: 632500 | H10: =IF(' BENGALURU HOUSE PRICE'!$G10<=500000,"Low", IF(' BENGALURU HOUSE PRICE'!$G10<=1000000,"Medium", IF(' BENGALURU HOUSE PRICE'!$G10<=3000000,"High","Luxury"))) -> Medium
A11: Gandhi Bazar | B11: 1020 | C11: 6 | D11: 2 | E11: 6 | F11: =IF(B11>2000,"Large",IF(B11>1000,"Medium","Small")) -> Medium | G11: 3700000 | H11: =IF(' BENGALURU HOUSE PRICE'!$G11<=500000,"Low", IF(' BENGALURU HOUSE PRICE'!$G11<=1000000,"Medium", IF(' BENGALURU HOUSE PRICE'!$G11<=3000000,"High","Luxury"))) -> Luxury
A12: Whitefield | B12: 1800 | C12: 2 | D12: 2 | E12: 3 | F12: =IF(B12>2000,"Large",IF(B12>1000,"Medium","Small")) -> Medium | G12: 700000 | H12: =IF(' BENGALURU HOUSE PRICE'!$G12<=500000,"Low", IF(' BENGALURU HOUSE PRICE'!$G12<=1000000,"Medium", IF(' BENGALURU HOUSE PRICE'!$G12<=3000000,"High","Luxury"))) -> Medium
A13: Whitefield | B13: 2785 | C13: 5 | D13: 3 | E13: 4 | F13: =IF(B13>2000,"Large",IF(B13>1000,"Medium","Small")) -> Large | G13: 2950000 | H13: =IF(' BENGALURU HOUSE PRICE'!$G13<=500000,"Low", IF(' BENGALURU HOUSE PRICE'!$G13<=1000000,"Medium", IF(' BENGALURU HOUSE PRICE'!$G13<=3000000,"High","Luxury"))) -> High
... A580: Harlur | B580: 1460 | C580: 3 | D580: 1 | E580: 3 | F580: =IF(B580>2000,"Large",IF(B580>1000,"Medium","Small")) -> Medium | G580: 730000 | H580: =IF(' BENGALURU HOUSE PRICE'!$G580<=500000,"Low", IF(' BENGALURU HOUSE PRICE'!$G580<=1000000,"Medium", IF(' BENGALURU HOUSE PRICE'!$G580<=3000000,"High","Luxury"))) -> Medium
A581: Sarjapur Road | B581: 1559 | C581: 2 | D581: 2 | F581: =IF(B581>2000,"Large",IF(B581>1000,"Medium","Small")) -> Medium | G581: 341850 | H581: =IF(' BENGALURU HOUSE PRICE'!$G581<=500000,"Low", IF(' BENGALURU HOUSE PRICE'!$G581<=1000000,"Medium", IF(' BENGALURU HOUSE PRICE'!$G581<=3000000,"High","Luxury"))) -> Low
A582: Gottigere | B582: 967 | C582: 2 | D582: 3 | E582: 2 | F582: =IF(B582>2000,"Large",IF(B582>1000,"Medium","Small")) -> Small | G582: 450000 | H582: =IF(' BENGALURU HOUSE PRICE'!$G582<=500000,"Low", IF(' BENGALURU HOUSE PRICE'!$G582<=1000000,"Medium", IF(' BENGALURU HOUSE PRICE'!$G582<=3000000,"High","Luxury"))) -> Low
A583: Byatarayanapura | B583: 540 | C583: 1 | D583: 1 | E583: 1 | F583: =IF(B583>2000,"Large",IF(B583>1000,"Medium","Small")) -> Small | G583: 360000 | H583: =IF(' BENGALURU HOUSE PRICE'!$G583<=500000,"Low", IF(' BENGALURU HOUSE PRICE'!$G583<=1000000,"Medium", IF(' BENGALURU HOUSE PRICE'!$G583<=3000000,"High","Luxury"))) -> Low
A584: Hormavu | B584: 715 | C584: 1 | D584: 2 | E584: 1 | F584: =IF(B584>2000,"Large",IF(B584>1000,"Medium","Small")) -> Small | G584: 460000 | H584: =IF(' BENGALURU HOUSE PRICE'!$G584<=500000,"Low", IF(' BENGALURU HOUSE PRICE'!$G584<=1000000,"Medium", IF(' BENGALURU HOUSE PRICE'!$G584<=3000000,"High","Luxury"))) -> Low
A585: Whitefield | B585: 2500 | C585: 3 | D585: 2 | E585: 3 | F585: =IF(B585>2000,"Large",IF(B585>1000,"Medium","Small")) -> Large | G585: 3130000 | H585: =IF(' BENGALURU HOUSE PRICE'!$G585<=500000,"Low", IF(' BENGALURU HOUSE PRICE'!$G585<=1000000,"Medium", IF(' BENGALURU HOUSE PRICE'!$G585<=3000000,"High","Luxury"))) -> Luxury
A586: Dooravani Nagar | B586: 1578 | C586: 3 | D586: 1 | E586: 3 | F586: =IF(B586>2000,"Large",IF(B586>1000,"Medium","Small")) -> Medium | G586: 1800000 | H586: =IF(' BENGALURU HOUSE PRICE'!$G586<=500000,"Low", IF(' BENGALURU HOUSE PRICE'!$G586<=1000000,"Medium", IF(' BENGALURU HOUSE PRICE'!$G586<=3000000,"High","Luxury"))) -> High
A587: Mysore Road | B587: 1020 | C587: 2 | D587: 1 | E587: 2 | F587: =IF(B587>2000,"Large",IF(B587>1000,"Medium","Small")) -> Medium | G587: 489500 | H587: =IF(' BENGALURU HOUSE PRICE'!$G587<=500000,"Low", IF(' BENGALURU HOUSE PRICE'!$G587<=1000000,"Medium", IF(' BENGALURU HOUSE PRICE'!$G587<=3000000,"High","Luxury"))) -> Low
A588: Jigani | B588: 1020 | C588: 2 | D588: 1 | E588: 2 | F588: =IF(B588>2000,"Large",IF(B588>1000,"Medium","Small")) -> Medium | G588: 400000 | H588: =IF(' BENGALURU HOUSE PRICE'!$G588<=500000,"Low", IF(' BENGALURU HOUSE PRICE'!$G588<=1000000,"Medium", IF(' BENGALURU HOUSE PRICE'!$G588<=3000000,"High","Luxury"))) -> Low
A589: Koramangala | B589: 1253 | C589: 2 | D589: 1 | E589: 2 | F589: =IF(B589>2000,"Large",IF(B589>1000,"Medium","Small")) -> Medium | G589: 1020000 | H589: =IF(' BENGALURU HOUSE PRICE'!$G589<=500000,"Low", IF(' BENGALURU HOUSE PRICE'!$G589<=1000000,"Medium", IF(' BENGALURU HOUSE PRICE'!$G589<=3000000,"High","Luxury"))) -> High
A590: JCR Layout | B590: 1180 | C590: 2 | D590: 2 | E590: 2 | F590: =IF(B590>2000,"Large",IF(B590>1000,"Medium","Small")) -> Medium | G590: 420000 | H590: =IF(' BENGALURU HOUSE PRICE'!$G590<=500000,"Low", IF(' BENGALURU HOUSE PRICE'!$G590<=1000000,"Medium", IF(' BENGALURU HOUSE PRICE'!$G590<=3000000,"High","Luxury"))) -> Low
A591: Nehru Nagar | B591: 961 | C591: 2 | D591: 2 | E591: 2 | F591: =IF(B591>2000,"Large",IF(B591>1000,"Medium","Small")) -> Small | G591: 380000 | H591: =IF(' BENGALURU HOUSE PRICE'!$G591<=500000,"Low", IF(' BENGALURU HOUSE PRICE'!$G591<=1000000,"Medium", IF(' BENGALURU HOUSE PRICE'!$G591<=3000000,"High","Luxury"))) -> Low
A592: Kanakapura | B592: 1419 | C592: 3 | D592: 3 | E592: 3 | F592: =IF(B592>2000,"Large",IF(B592>1000,"Medium","Small")) -> Medium | G592: 750000 | H592: =IF(' BENGALURU HOUSE PRICE'!$G592<=500000,"Low", IF(' BENGALURU HOUSE PRICE'!$G592<=1000000,"Medium", IF(' BENGALURU HOUSE PRICE'!$G592<=3000000,"High","Luxury"))) -> Medium
A593: Harlur | B593: 1709 | C593: 3 | D593: 2 | E593: 3 | F593: =IF(B593>2000,"Large",IF(B593>1000,"Medium","Small")) -> Medium | G593: 1500000 | H593: =IF(' BENGALURU HOUSE PRICE'!$G593<=500000,"Low", IF(' BENGALURU HOUSE PRICE'!$G593<=1000000,"Medium", IF(' BENGALURU HOUSE PRICE'!$G593<=3000000,"High","Luxury"))) -> High
... A1256: Raja Rajeshwari Nagar | B1256: 500 | C1256: 1 | D1256: 1 | E1256: 1 | F1256: =IF(B1256>2000,"Large",IF(B1256>1000,"Medium","Small")) -> Small | G1256: 250000 | H1256: =IF(' BENGALURU HOUSE PRICE'!$G1256<=500000,"Low", IF(' BENGALURU HOUSE PRICE'!$G1256<=1000000,"Medium", IF(' BENGALURU HOUSE PRICE'!$G1256<=3000000,"High","Luxury"))) -> Low
